2019-12-12 18:13:58,257 - D:/project/face-recognition-service/log.py[line:43] - ERROR: error
